[2025-01-16T15:30:08.493+0000] {local_task_job_runner.py:123} INFO - ::group::Pre task execution logs
[2025-01-16T15:30:08.594+0000] {taskinstance.py:2613} INFO - Dependencies all met for dep_context=non-requeueable deps ti=<TaskInstance: movie_pipeline.scrape_filmmakers manual__2025-01-16T04:38:13.822674+00:00 [queued]>
[2025-01-16T15:30:08.625+0000] {taskinstance.py:2613} INFO - Dependencies all met for dep_context=requeueable deps ti=<TaskInstance: movie_pipeline.scrape_filmmakers manual__2025-01-16T04:38:13.822674+00:00 [queued]>
[2025-01-16T15:30:08.626+0000] {taskinstance.py:2866} INFO - Starting attempt 1 of 1
[2025-01-16T15:30:08.671+0000] {taskinstance.py:2889} INFO - Executing <Task(PythonOperator): scrape_filmmakers> on 2025-01-16 04:38:13.822674+00:00
[2025-01-16T15:30:08.685+0000] {standard_task_runner.py:72} INFO - Started process 1772 to run task
[2025-01-16T15:30:08.692+0000] {standard_task_runner.py:104} INFO - Running: ['airflow', 'tasks', 'run', 'movie_pipeline', 'scrape_filmmakers', 'manual__2025-01-16T04:38:13.822674+00:00', '--job-id', '38', '--raw', '--subdir', 'DAGS_FOLDER/pipeline_dag.py', '--cfg-path', '/tmp/tmpmb6ybcgm']
[2025-01-16T15:30:08.700+0000] {standard_task_runner.py:105} INFO - Job 38: Subtask scrape_filmmakers
[2025-01-16T15:30:08.924+0000] {task_command.py:467} INFO - Running <TaskInstance: movie_pipeline.scrape_filmmakers manual__2025-01-16T04:38:13.822674+00:00 [running]> on host 2dad824ef9ce
[2025-01-16T15:30:09.512+0000] {taskinstance.py:3132} INFO - Exporting env vars: AIRFLOW_CTX_DAG_OWNER='airflow' AIRFLOW_CTX_DAG_ID='movie_pipeline' AIRFLOW_CTX_TASK_ID='scrape_filmmakers' AIRFLOW_CTX_EXECUTION_DATE='2025-01-16T04:38:13.822674+00:00' AIRFLOW_CTX_TRY_NUMBER='1' AIRFLOW_CTX_DAG_RUN_ID='manual__2025-01-16T04:38:13.822674+00:00'
[2025-01-16T15:30:09.515+0000] {taskinstance.py:731} INFO - ::endgroup::
[2025-01-16T15:30:20.628+0000] {extract.py:154} INFO - movie iteration 0 and filmamker iteration 0 for movie_id : tt13186482 and filmmaker_id: nm1503575
[2025-01-16T15:32:03.106+0000] {extract.py:154} INFO - movie iteration 0 and filmamker iteration 1 for movie_id : tt13186482 and filmmaker_id: nm0622288
[2025-01-16T15:33:31.674+0000] {extract.py:154} INFO - movie iteration 0 and filmamker iteration 2 for movie_id : tt13186482 and filmmaker_id: nm0941314
[2025-01-16T15:33:32.264+0000] {local_task_job_runner.py:346} WARNING - State of this instance has been externally set to failed. Terminating instance.
[2025-01-16T15:33:32.472+0000] {local_task_job_runner.py:245} INFO - ::endgroup::
[2025-01-16T15:33:32.512+0000] {process_utils.py:132} INFO - Sending 15 to group 1772. PIDs of all processes in the group: [1821, 1837, 1850, 1851, 1878, 1882, 1964, 1890, 1965, 2113, 3077, 3116, 3136, 1954, 1772]
[2025-01-16T15:33:32.520+0000] {process_utils.py:87} INFO - Sending the signal 15 to group 1772
[2025-01-16T15:33:32.572+0000] {taskinstance.py:3093} ERROR - Received SIGTERM. Terminating subprocesses.
[2025-01-16T15:33:32.690+0000] {connectionpool.py:827} WARNING - Retrying (Retry(total=2, connect=None, read=None, redirect=None, status=None)) after connection broken by 'NewConnectionError('<urllib3.connection.HTTPConnection object at 0x7f3a0da24a90>: Failed to establish a new connection: [Errno 111] Connection refused')': /session/27ff6abf56bb11c1b07d24e0e26e3abe/window
[2025-01-16T15:33:32.700+0000] {connectionpool.py:827} WARNING - Retrying (Retry(total=1, connect=None, read=None, redirect=None, status=None)) after connection broken by 'NewConnectionError('<urllib3.connection.HTTPConnection object at 0x7f3a0da24fa0>: Failed to establish a new connection: [Errno 111] Connection refused')': /session/27ff6abf56bb11c1b07d24e0e26e3abe/window
[2025-01-16T15:33:32.711+0000] {connectionpool.py:827} WARNING - Retrying (Retry(total=0, connect=None, read=None, redirect=None, status=None)) after connection broken by 'NewConnectionError('<urllib3.connection.HTTPConnection object at 0x7f3a0da24bb0>: Failed to establish a new connection: [Errno 111] Connection refused')': /session/27ff6abf56bb11c1b07d24e0e26e3abe/window
[2025-01-16T15:33:32.718+0000] {process_utils.py:80} INFO - Process psutil.Process(pid=3116, status='terminated', started='15:33:23') (3116) terminated with exit code None
[2025-01-16T15:33:32.731+0000] {process_utils.py:80} INFO - Process psutil.Process(pid=1965, status='terminated', started='15:30:10') (1965) terminated with exit code None
[2025-01-16T15:33:32.819+0000] {process_utils.py:80} INFO - Process psutil.Process(pid=1882, status='terminated', started='15:30:09') (1882) terminated with exit code None
[2025-01-16T15:33:32.827+0000] {process_utils.py:80} INFO - Process psutil.Process(pid=3077, status='terminated', started='15:33:09') (3077) terminated with exit code None
[2025-01-16T15:33:32.831+0000] {process_utils.py:80} INFO - Process psutil.Process(pid=1850, status='terminated', started='15:30:09') (1850) terminated with exit code None
[2025-01-16T15:33:32.843+0000] {process_utils.py:80} INFO - Process psutil.Process(pid=1837, status='terminated', started='15:30:09') (1837) terminated with exit code None
[2025-01-16T15:33:32.728+0000] {taskinstance.py:3311} ERROR - Task failed with exception
Traceback (most recent call last):
  File "/opt/src/extract_scripts/extract.py", line 175, in movie_cast_filmmakers_extract
    driver.get(link)
  File "/home/airflow/.local/lib/python3.9/site-packages/selenium/webdriver/remote/webdriver.py", line 393, in get
    self.execute(Command.GET, {"url": url})
  File "/home/airflow/.local/lib/python3.9/site-packages/selenium/webdriver/remote/webdriver.py", line 382, in execute
    response = self.command_executor.execute(driver_command, params)
  File "/home/airflow/.local/lib/python3.9/site-packages/selenium/webdriver/remote/remote_connection.py", line 404, in execute
    return self._request(command_info[0], url, body=data)
  File "/home/airflow/.local/lib/python3.9/site-packages/selenium/webdriver/remote/remote_connection.py", line 428, in _request
    response = self._conn.request(method, url, body=body, headers=headers, timeout=self._client_config.timeout)
  File "/home/airflow/.local/lib/python3.9/site-packages/urllib3/request.py", line 81, in request
    return self.request_encode_body(
  File "/home/airflow/.local/lib/python3.9/site-packages/urllib3/request.py", line 173, in request_encode_body
    return self.urlopen(method, url, **extra_kw)
  File "/home/airflow/.local/lib/python3.9/site-packages/urllib3/poolmanager.py", line 376, in urlopen
    response = conn.urlopen(method, u.request_uri, **kw)
  File "/home/airflow/.local/lib/python3.9/site-packages/urllib3/connectionpool.py", line 716, in urlopen
    httplib_response = self._make_request(
  File "/home/airflow/.local/lib/python3.9/site-packages/urllib3/connectionpool.py", line 468, in _make_request
    six.raise_from(e, None)
  File "<string>", line 3, in raise_from
  File "/home/airflow/.local/lib/python3.9/site-packages/urllib3/connectionpool.py", line 463, in _make_request
    httplib_response = conn.getresponse()
  File "/usr/local/lib/python3.9/http/client.py", line 1377, in getresponse
    response.begin()
  File "/usr/local/lib/python3.9/http/client.py", line 320, in begin
    version, status, reason = self._read_status()
  File "/usr/local/lib/python3.9/http/client.py", line 281, in _read_status
    line = str(self.fp.readline(_MAXLINE + 1), "iso-8859-1")
  File "/usr/local/lib/python3.9/socket.py", line 716, in readinto
    return self._sock.recv_into(b)
  File "/home/airflow/.local/lib/python3.9/site-packages/airflow/models/taskinstance.py", line 3095, in signal_handler
    raise AirflowTaskTerminated("Task received SIGTERM signal")
airflow.exceptions.AirflowTaskTerminated: Task received SIGTERM signal

During handling of the above exception, another exception occurred:

Traceback (most recent call last):
  File "/home/airflow/.local/lib/python3.9/site-packages/urllib3/connection.py", line 174, in _new_conn
    conn = connection.create_connection(
  File "/home/airflow/.local/lib/python3.9/site-packages/urllib3/util/connection.py", line 95, in create_connection
    raise err
  File "/home/airflow/.local/lib/python3.9/site-packages/urllib3/util/connection.py", line 85, in create_connection
    sock.connect(sa)
ConnectionRefusedError: [Errno 111] Connection refused

During handling of the above exception, another exception occurred:

Traceback (most recent call last):
  File "/home/airflow/.local/lib/python3.9/site-packages/urllib3/connectionpool.py", line 716, in urlopen
    httplib_response = self._make_request(
  File "/home/airflow/.local/lib/python3.9/site-packages/urllib3/connectionpool.py", line 416, in _make_request
    conn.request(method, url, **httplib_request_kw)
  File "/home/airflow/.local/lib/python3.9/site-packages/urllib3/connection.py", line 244, in request
    super(HTTPConnection, self).request(method, url, body=body, headers=headers)
  File "/usr/local/lib/python3.9/http/client.py", line 1285, in request
    self._send_request(method, url, body, headers, encode_chunked)
  File "/usr/local/lib/python3.9/http/client.py", line 1331, in _send_request
    self.endheaders(body, encode_chunked=encode_chunked)
  File "/usr/local/lib/python3.9/http/client.py", line 1280, in endheaders
    self._send_output(message_body, encode_chunked=encode_chunked)
  File "/usr/local/lib/python3.9/http/client.py", line 1040, in _send_output
    self.send(msg)
  File "/usr/local/lib/python3.9/http/client.py", line 980, in send
    self.connect()
  File "/home/airflow/.local/lib/python3.9/site-packages/urllib3/connection.py", line 205, in connect
    conn = self._new_conn()
  File "/home/airflow/.local/lib/python3.9/site-packages/urllib3/connection.py", line 186, in _new_conn
    raise NewConnectionError(
urllib3.exceptions.NewConnectionError: <urllib3.connection.HTTPConnection object at 0x7f3a0da24d00>: Failed to establish a new connection: [Errno 111] Connection refused

During handling of the above exception, another exception occurred:

Traceback (most recent call last):
  File "/home/airflow/.local/lib/python3.9/site-packages/airflow/models/taskinstance.py", line 767, in _execute_task
    result = _execute_callable(context=context, **execute_callable_kwargs)
  File "/home/airflow/.local/lib/python3.9/site-packages/airflow/models/taskinstance.py", line 733, in _execute_callable
    return ExecutionCallableRunner(
  File "/home/airflow/.local/lib/python3.9/site-packages/airflow/utils/operator_helpers.py", line 252, in run
    return self.func(*args, **kwargs)
  File "/home/airflow/.local/lib/python3.9/site-packages/airflow/models/baseoperator.py", line 422, in wrapper
    return func(self, *args, **kwargs)
  File "/home/airflow/.local/lib/python3.9/site-packages/airflow/operators/python.py", line 238, in execute
    return_value = self.execute_callable()
  File "/home/airflow/.local/lib/python3.9/site-packages/airflow/operators/python.py", line 256, in execute_callable
    return runner.run(*self.op_args, **self.op_kwargs)
  File "/home/airflow/.local/lib/python3.9/site-packages/airflow/utils/operator_helpers.py", line 252, in run
    return self.func(*args, **kwargs)
  File "/opt/src/extract_scripts/extract.py", line 192, in movie_cast_filmmakers_extract
    driver.close()
  File "/home/airflow/.local/lib/python3.9/site-packages/selenium/webdriver/remote/webdriver.py", line 495, in close
    self.execute(Command.CLOSE)
  File "/home/airflow/.local/lib/python3.9/site-packages/selenium/webdriver/remote/webdriver.py", line 382, in execute
    response = self.command_executor.execute(driver_command, params)
  File "/home/airflow/.local/lib/python3.9/site-packages/selenium/webdriver/remote/remote_connection.py", line 404, in execute
    return self._request(command_info[0], url, body=data)
  File "/home/airflow/.local/lib/python3.9/site-packages/selenium/webdriver/remote/remote_connection.py", line 428, in _request
    response = self._conn.request(method, url, body=body, headers=headers, timeout=self._client_config.timeout)
  File "/home/airflow/.local/lib/python3.9/site-packages/urllib3/request.py", line 77, in request
    return self.request_encode_url(
  File "/home/airflow/.local/lib/python3.9/site-packages/urllib3/request.py", line 99, in request_encode_url
    return self.urlopen(method, url, **extra_kw)
  File "/home/airflow/.local/lib/python3.9/site-packages/urllib3/poolmanager.py", line 376, in urlopen
    response = conn.urlopen(method, u.request_uri, **kw)
  File "/home/airflow/.local/lib/python3.9/site-packages/urllib3/connectionpool.py", line 830, in urlopen
    return self.urlopen(
  File "/home/airflow/.local/lib/python3.9/site-packages/urllib3/connectionpool.py", line 830, in urlopen
    return self.urlopen(
  File "/home/airflow/.local/lib/python3.9/site-packages/urllib3/connectionpool.py", line 830, in urlopen
    return self.urlopen(
  File "/home/airflow/.local/lib/python3.9/site-packages/urllib3/connectionpool.py", line 802, in urlopen
    retries = retries.increment(
  File "/home/airflow/.local/lib/python3.9/site-packages/urllib3/util/retry.py", line 594, in increment
    raise MaxRetryError(_pool, url, error or ResponseError(cause))
urllib3.exceptions.MaxRetryError: HTTPConnectionPool(host='localhost', port=58867): Max retries exceeded with url: /session/27ff6abf56bb11c1b07d24e0e26e3abe/window (Caused by NewConnectionError('<urllib3.connection.HTTPConnection object at 0x7f3a0da24d00>: Failed to establish a new connection: [Errno 111] Connection refused'))
[2025-01-16T15:33:32.958+0000] {process_utils.py:80} INFO - Process psutil.Process(pid=1878, status='terminated', started='15:30:09') (1878) terminated with exit code None
[2025-01-16T15:33:32.964+0000] {process_utils.py:80} INFO - Process psutil.Process(pid=3136, status='terminated', started='15:33:28') (3136) terminated with exit code None
[2025-01-16T15:33:32.970+0000] {process_utils.py:80} INFO - Process psutil.Process(pid=1890, status='terminated', started='15:30:09') (1890) terminated with exit code None
[2025-01-16T15:33:32.977+0000] {process_utils.py:80} INFO - Process psutil.Process(pid=1954, status='terminated', started='15:30:09') (1954) terminated with exit code None
[2025-01-16T15:33:32.997+0000] {taskinstance.py:1225} INFO - Marking task as FAILED. dag_id=movie_pipeline, task_id=scrape_filmmakers, run_id=manual__2025-01-16T04:38:13.822674+00:00, execution_date=20250116T043813, start_date=20250116T153008, end_date=20250116T153332
[2025-01-16T15:33:33.087+0000] {process_utils.py:80} INFO - Process psutil.Process(pid=1964, status='terminated', started='15:30:09') (1964) terminated with exit code None
[2025-01-16T15:33:33.092+0000] {process_utils.py:80} INFO - Process psutil.Process(pid=2113, status='terminated', started='15:30:11') (2113) terminated with exit code None
[2025-01-16T15:33:33.094+0000] {process_utils.py:80} INFO - Process psutil.Process(pid=1851, status='terminated', started='15:30:09') (1851) terminated with exit code None
[2025-01-16T15:33:33.139+0000] {taskinstance.py:340} INFO - ::group::Post task execution logs
[2025-01-16T15:33:33.142+0000] {standard_task_runner.py:124} ERROR - Failed to execute job 38 for task scrape_filmmakers (HTTPConnectionPool(host='localhost', port=58867): Max retries exceeded with url: /session/27ff6abf56bb11c1b07d24e0e26e3abe/window (Caused by NewConnectionError('<urllib3.connection.HTTPConnection object at 0x7f3a0da24d00>: Failed to establish a new connection: [Errno 111] Connection refused')); 1772)
Traceback (most recent call last):
  File "/opt/src/extract_scripts/extract.py", line 175, in movie_cast_filmmakers_extract
    driver.get(link)
  File "/home/airflow/.local/lib/python3.9/site-packages/selenium/webdriver/remote/webdriver.py", line 393, in get
    self.execute(Command.GET, {"url": url})
  File "/home/airflow/.local/lib/python3.9/site-packages/selenium/webdriver/remote/webdriver.py", line 382, in execute
    response = self.command_executor.execute(driver_command, params)
  File "/home/airflow/.local/lib/python3.9/site-packages/selenium/webdriver/remote/remote_connection.py", line 404, in execute
    return self._request(command_info[0], url, body=data)
  File "/home/airflow/.local/lib/python3.9/site-packages/selenium/webdriver/remote/remote_connection.py", line 428, in _request
    response = self._conn.request(method, url, body=body, headers=headers, timeout=self._client_config.timeout)
  File "/home/airflow/.local/lib/python3.9/site-packages/urllib3/request.py", line 81, in request
    return self.request_encode_body(
  File "/home/airflow/.local/lib/python3.9/site-packages/urllib3/request.py", line 173, in request_encode_body
    return self.urlopen(method, url, **extra_kw)
  File "/home/airflow/.local/lib/python3.9/site-packages/urllib3/poolmanager.py", line 376, in urlopen
    response = conn.urlopen(method, u.request_uri, **kw)
  File "/home/airflow/.local/lib/python3.9/site-packages/urllib3/connectionpool.py", line 716, in urlopen
    httplib_response = self._make_request(
  File "/home/airflow/.local/lib/python3.9/site-packages/urllib3/connectionpool.py", line 468, in _make_request
    six.raise_from(e, None)
  File "<string>", line 3, in raise_from
  File "/home/airflow/.local/lib/python3.9/site-packages/urllib3/connectionpool.py", line 463, in _make_request
    httplib_response = conn.getresponse()
  File "/usr/local/lib/python3.9/http/client.py", line 1377, in getresponse
    response.begin()
  File "/usr/local/lib/python3.9/http/client.py", line 320, in begin
    version, status, reason = self._read_status()
  File "/usr/local/lib/python3.9/http/client.py", line 281, in _read_status
    line = str(self.fp.readline(_MAXLINE + 1), "iso-8859-1")
  File "/usr/local/lib/python3.9/socket.py", line 716, in readinto
    return self._sock.recv_into(b)
  File "/home/airflow/.local/lib/python3.9/site-packages/airflow/models/taskinstance.py", line 3095, in signal_handler
    raise AirflowTaskTerminated("Task received SIGTERM signal")
airflow.exceptions.AirflowTaskTerminated: Task received SIGTERM signal

During handling of the above exception, another exception occurred:

Traceback (most recent call last):
  File "/home/airflow/.local/lib/python3.9/site-packages/urllib3/connection.py", line 174, in _new_conn
    conn = connection.create_connection(
  File "/home/airflow/.local/lib/python3.9/site-packages/urllib3/util/connection.py", line 95, in create_connection
    raise err
  File "/home/airflow/.local/lib/python3.9/site-packages/urllib3/util/connection.py", line 85, in create_connection
    sock.connect(sa)
ConnectionRefusedError: [Errno 111] Connection refused

During handling of the above exception, another exception occurred:

Traceback (most recent call last):
  File "/home/airflow/.local/lib/python3.9/site-packages/urllib3/connectionpool.py", line 716, in urlopen
    httplib_response = self._make_request(
  File "/home/airflow/.local/lib/python3.9/site-packages/urllib3/connectionpool.py", line 416, in _make_request
    conn.request(method, url, **httplib_request_kw)
  File "/home/airflow/.local/lib/python3.9/site-packages/urllib3/connection.py", line 244, in request
    super(HTTPConnection, self).request(method, url, body=body, headers=headers)
  File "/usr/local/lib/python3.9/http/client.py", line 1285, in request
    self._send_request(method, url, body, headers, encode_chunked)
  File "/usr/local/lib/python3.9/http/client.py", line 1331, in _send_request
    self.endheaders(body, encode_chunked=encode_chunked)
  File "/usr/local/lib/python3.9/http/client.py", line 1280, in endheaders
    self._send_output(message_body, encode_chunked=encode_chunked)
  File "/usr/local/lib/python3.9/http/client.py", line 1040, in _send_output
    self.send(msg)
  File "/usr/local/lib/python3.9/http/client.py", line 980, in send
    self.connect()
  File "/home/airflow/.local/lib/python3.9/site-packages/urllib3/connection.py", line 205, in connect
    conn = self._new_conn()
  File "/home/airflow/.local/lib/python3.9/site-packages/urllib3/connection.py", line 186, in _new_conn
    raise NewConnectionError(
urllib3.exceptions.NewConnectionError: <urllib3.connection.HTTPConnection object at 0x7f3a0da24d00>: Failed to establish a new connection: [Errno 111] Connection refused

During handling of the above exception, another exception occurred:

Traceback (most recent call last):
  File "/home/airflow/.local/lib/python3.9/site-packages/airflow/task/task_runner/standard_task_runner.py", line 117, in _start_by_fork
    ret = args.func(args, dag=self.dag)
  File "/home/airflow/.local/lib/python3.9/site-packages/airflow/cli/cli_config.py", line 49, in command
    return func(*args, **kwargs)
  File "/home/airflow/.local/lib/python3.9/site-packages/airflow/utils/cli.py", line 116, in wrapper
    return f(*args, **kwargs)
  File "/home/airflow/.local/lib/python3.9/site-packages/airflow/cli/commands/task_command.py", line 483, in task_run
    task_return_code = _run_task_by_selected_method(args, _dag, ti)
  File "/home/airflow/.local/lib/python3.9/site-packages/airflow/cli/commands/task_command.py", line 256, in _run_task_by_selected_method
    return _run_raw_task(args, ti)
  File "/home/airflow/.local/lib/python3.9/site-packages/airflow/cli/commands/task_command.py", line 341, in _run_raw_task
    return ti._run_raw_task(
  File "/home/airflow/.local/lib/python3.9/site-packages/airflow/utils/session.py", line 97, in wrapper
    return func(*args, session=session, **kwargs)
  File "/home/airflow/.local/lib/python3.9/site-packages/airflow/models/taskinstance.py", line 3005, in _run_raw_task
    return _run_raw_task(
  File "/home/airflow/.local/lib/python3.9/site-packages/airflow/models/taskinstance.py", line 273, in _run_raw_task
    TaskInstance._execute_task_with_callbacks(
  File "/home/airflow/.local/lib/python3.9/site-packages/airflow/models/taskinstance.py", line 3159, in _execute_task_with_callbacks
    result = self._execute_task(context, task_orig)
  File "/home/airflow/.local/lib/python3.9/site-packages/airflow/models/taskinstance.py", line 3183, in _execute_task
    return _execute_task(self, context, task_orig)
  File "/home/airflow/.local/lib/python3.9/site-packages/airflow/models/taskinstance.py", line 767, in _execute_task
    result = _execute_callable(context=context, **execute_callable_kwargs)
  File "/home/airflow/.local/lib/python3.9/site-packages/airflow/models/taskinstance.py", line 733, in _execute_callable
    return ExecutionCallableRunner(
  File "/home/airflow/.local/lib/python3.9/site-packages/airflow/utils/operator_helpers.py", line 252, in run
    return self.func(*args, **kwargs)
  File "/home/airflow/.local/lib/python3.9/site-packages/airflow/models/baseoperator.py", line 422, in wrapper
    return func(self, *args, **kwargs)
  File "/home/airflow/.local/lib/python3.9/site-packages/airflow/operators/python.py", line 238, in execute
    return_value = self.execute_callable()
  File "/home/airflow/.local/lib/python3.9/site-packages/airflow/operators/python.py", line 256, in execute_callable
    return runner.run(*self.op_args, **self.op_kwargs)
  File "/home/airflow/.local/lib/python3.9/site-packages/airflow/utils/operator_helpers.py", line 252, in run
    return self.func(*args, **kwargs)
  File "/opt/src/extract_scripts/extract.py", line 192, in movie_cast_filmmakers_extract
    driver.close()
  File "/home/airflow/.local/lib/python3.9/site-packages/selenium/webdriver/remote/webdriver.py", line 495, in close
    self.execute(Command.CLOSE)
  File "/home/airflow/.local/lib/python3.9/site-packages/selenium/webdriver/remote/webdriver.py", line 382, in execute
    response = self.command_executor.execute(driver_command, params)
  File "/home/airflow/.local/lib/python3.9/site-packages/selenium/webdriver/remote/remote_connection.py", line 404, in execute
    return self._request(command_info[0], url, body=data)
  File "/home/airflow/.local/lib/python3.9/site-packages/selenium/webdriver/remote/remote_connection.py", line 428, in _request
    response = self._conn.request(method, url, body=body, headers=headers, timeout=self._client_config.timeout)
  File "/home/airflow/.local/lib/python3.9/site-packages/urllib3/request.py", line 77, in request
    return self.request_encode_url(
  File "/home/airflow/.local/lib/python3.9/site-packages/urllib3/request.py", line 99, in request_encode_url
    return self.urlopen(method, url, **extra_kw)
  File "/home/airflow/.local/lib/python3.9/site-packages/urllib3/poolmanager.py", line 376, in urlopen
    response = conn.urlopen(method, u.request_uri, **kw)
  File "/home/airflow/.local/lib/python3.9/site-packages/urllib3/connectionpool.py", line 830, in urlopen
    return self.urlopen(
  File "/home/airflow/.local/lib/python3.9/site-packages/urllib3/connectionpool.py", line 830, in urlopen
    return self.urlopen(
  File "/home/airflow/.local/lib/python3.9/site-packages/urllib3/connectionpool.py", line 830, in urlopen
    return self.urlopen(
  File "/home/airflow/.local/lib/python3.9/site-packages/urllib3/connectionpool.py", line 802, in urlopen
    retries = retries.increment(
  File "/home/airflow/.local/lib/python3.9/site-packages/urllib3/util/retry.py", line 594, in increment
    raise MaxRetryError(_pool, url, error or ResponseError(cause))
urllib3.exceptions.MaxRetryError: HTTPConnectionPool(host='localhost', port=58867): Max retries exceeded with url: /session/27ff6abf56bb11c1b07d24e0e26e3abe/window (Caused by NewConnectionError('<urllib3.connection.HTTPConnection object at 0x7f3a0da24d00>: Failed to establish a new connection: [Errno 111] Connection refused'))
[2025-01-16T15:33:33.197+0000] {process_utils.py:80} INFO - Process psutil.Process(pid=1821, status='terminated', started='15:30:09') (1821) terminated with exit code None
[2025-01-16T15:33:33.200+0000] {process_utils.py:80} INFO - Process psutil.Process(pid=1772, status='terminated', exitcode=1, started='15:30:07') (1772) terminated with exit code 1
