[2025-01-16T15:30:08.583+0000] {local_task_job_runner.py:123} INFO - ::group::Pre task execution logs
[2025-01-16T15:30:08.650+0000] {taskinstance.py:2613} INFO - Dependencies all met for dep_context=non-requeueable deps ti=<TaskInstance: movie_pipeline.scrape_genre manual__2025-01-16T04:38:13.822674+00:00 [queued]>
[2025-01-16T15:30:08.674+0000] {taskinstance.py:2613} INFO - Dependencies all met for dep_context=requeueable deps ti=<TaskInstance: movie_pipeline.scrape_genre manual__2025-01-16T04:38:13.822674+00:00 [queued]>
[2025-01-16T15:30:08.675+0000] {taskinstance.py:2866} INFO - Starting attempt 1 of 1
[2025-01-16T15:30:08.720+0000] {taskinstance.py:2889} INFO - Executing <Task(PythonOperator): scrape_genre> on 2025-01-16 04:38:13.822674+00:00
[2025-01-16T15:30:08.736+0000] {standard_task_runner.py:72} INFO - Started process 1776 to run task
[2025-01-16T15:30:08.750+0000] {standard_task_runner.py:104} INFO - Running: ['airflow', 'tasks', 'run', 'movie_pipeline', 'scrape_genre', 'manual__2025-01-16T04:38:13.822674+00:00', '--job-id', '40', '--raw', '--subdir', 'DAGS_FOLDER/pipeline_dag.py', '--cfg-path', '/tmp/tmp41dih44e']
[2025-01-16T15:30:08.759+0000] {standard_task_runner.py:105} INFO - Job 40: Subtask scrape_genre
[2025-01-16T15:30:08.954+0000] {task_command.py:467} INFO - Running <TaskInstance: movie_pipeline.scrape_genre manual__2025-01-16T04:38:13.822674+00:00 [running]> on host 2dad824ef9ce
[2025-01-16T15:30:09.480+0000] {taskinstance.py:3132} INFO - Exporting env vars: AIRFLOW_CTX_DAG_OWNER='airflow' AIRFLOW_CTX_DAG_ID='movie_pipeline' AIRFLOW_CTX_TASK_ID='scrape_genre' AIRFLOW_CTX_EXECUTION_DATE='2025-01-16T04:38:13.822674+00:00' AIRFLOW_CTX_TRY_NUMBER='1' AIRFLOW_CTX_DAG_RUN_ID='manual__2025-01-16T04:38:13.822674+00:00'
[2025-01-16T15:30:09.487+0000] {taskinstance.py:731} INFO - ::endgroup::
[2025-01-16T15:30:23.701+0000] {extract.py:237} INFO - movie_iteration: 0, genre_iteration0 for movie_id: tt13186482 and genre_id: in0000092
[2025-01-16T15:31:40.992+0000] {extract.py:237} INFO - movie_iteration: 0, genre_iteration1 for movie_id: tt13186482 and genre_id: in0000028
[2025-01-16T15:32:38.243+0000] {extract.py:237} INFO - movie_iteration: 0, genre_iteration2 for movie_id: tt13186482 and genre_id: in0000012
[2025-01-16T15:33:07.116+0000] {extract.py:237} INFO - movie_iteration: 0, genre_iteration3 for movie_id: tt13186482 and genre_id: in0000026
[2025-01-16T15:33:32.189+0000] {local_task_job_runner.py:346} WARNING - State of this instance has been externally set to failed. Terminating instance.
[2025-01-16T15:33:32.396+0000] {local_task_job_runner.py:245} INFO - ::endgroup::
[2025-01-16T15:33:32.491+0000] {process_utils.py:132} INFO - Sending 15 to group 1776. PIDs of all processes in the group: [1822, 1838, 1852, 1853, 1867, 1871, 1963, 1900, 1966, 2121, 3044, 3092, 3137, 1958, 1776]
[2025-01-16T15:33:32.511+0000] {process_utils.py:87} INFO - Sending the signal 15 to group 1776
[2025-01-16T15:33:32.529+0000] {taskinstance.py:3093} ERROR - Received SIGTERM. Terminating subprocesses.
[2025-01-16T15:33:32.606+0000] {process_utils.py:80} INFO - Process psutil.Process(pid=3137, status='terminated', started='15:33:28') (3137) terminated with exit code None
[2025-01-16T15:33:32.693+0000] {connectionpool.py:827} WARNING - Retrying (Retry(total=2, connect=None, read=None, redirect=None, status=None)) after connection broken by 'NewConnectionError('<urllib3.connection.HTTPConnection object at 0x7f3a0da24dc0>: Failed to establish a new connection: [Errno 111] Connection refused')': /session/0965b632ea0d8fcd9aaffcaf37565c9a/window
[2025-01-16T15:33:32.698+0000] {connectionpool.py:827} WARNING - Retrying (Retry(total=1, connect=None, read=None, redirect=None, status=None)) after connection broken by 'NewConnectionError('<urllib3.connection.HTTPConnection object at 0x7f3a0da24fa0>: Failed to establish a new connection: [Errno 111] Connection refused')': /session/0965b632ea0d8fcd9aaffcaf37565c9a/window
[2025-01-16T15:33:32.714+0000] {connectionpool.py:827} WARNING - Retrying (Retry(total=0, connect=None, read=None, redirect=None, status=None)) after connection broken by 'NewConnectionError('<urllib3.connection.HTTPConnection object at 0x7f3a0da24eb0>: Failed to establish a new connection: [Errno 111] Connection refused')': /session/0965b632ea0d8fcd9aaffcaf37565c9a/window
[2025-01-16T15:33:32.713+0000] {process_utils.py:80} INFO - Process psutil.Process(pid=3092, status='terminated', started='15:33:20') (3092) terminated with exit code None
[2025-01-16T15:33:32.769+0000] {process_utils.py:80} INFO - Process psutil.Process(pid=1963, status='terminated', started='15:30:09') (1963) terminated with exit code None
[2025-01-16T15:33:32.837+0000] {process_utils.py:80} INFO - Process psutil.Process(pid=1871, status='terminated', started='15:30:09') (1871) terminated with exit code None
[2025-01-16T15:33:32.841+0000] {process_utils.py:80} INFO - Process psutil.Process(pid=1966, status='terminated', started='15:30:10') (1966) terminated with exit code None
[2025-01-16T15:33:32.845+0000] {process_utils.py:80} INFO - Process psutil.Process(pid=3044, status='terminated', started='15:33:03') (3044) terminated with exit code None
[2025-01-16T15:33:32.847+0000] {process_utils.py:80} INFO - Process psutil.Process(pid=1958, status='terminated', started='15:30:09') (1958) terminated with exit code None
[2025-01-16T15:33:32.849+0000] {process_utils.py:80} INFO - Process psutil.Process(pid=1867, status='terminated', started='15:30:09') (1867) terminated with exit code None
[2025-01-16T15:33:32.851+0000] {process_utils.py:80} INFO - Process psutil.Process(pid=1900, status='terminated', started='15:30:09') (1900) terminated with exit code None
[2025-01-16T15:33:32.853+0000] {process_utils.py:80} INFO - Process psutil.Process(pid=1838, status='terminated', started='15:30:09') (1838) terminated with exit code None
[2025-01-16T15:33:32.857+0000] {process_utils.py:80} INFO - Process psutil.Process(pid=1852, status='terminated', started='15:30:09') (1852) terminated with exit code None
[2025-01-16T15:33:32.859+0000] {process_utils.py:80} INFO - Process psutil.Process(pid=1853, status='terminated', started='15:30:09') (1853) terminated with exit code None
[2025-01-16T15:33:32.860+0000] {process_utils.py:80} INFO - Process psutil.Process(pid=2121, status='terminated', started='15:30:12') (2121) terminated with exit code None
[2025-01-16T15:33:32.735+0000] {taskinstance.py:3311} ERROR - Task failed with exception
Traceback (most recent call last):
  File "/opt/src/extract_scripts/extract.py", line 244, in genre_scraper
    driver.get(genre_link_us_box_office_collection_sorted)
  File "/home/airflow/.local/lib/python3.9/site-packages/selenium/webdriver/remote/webdriver.py", line 393, in get
    self.execute(Command.GET, {"url": url})
  File "/home/airflow/.local/lib/python3.9/site-packages/selenium/webdriver/remote/webdriver.py", line 382, in execute
    response = self.command_executor.execute(driver_command, params)
  File "/home/airflow/.local/lib/python3.9/site-packages/selenium/webdriver/remote/remote_connection.py", line 404, in execute
    return self._request(command_info[0], url, body=data)
  File "/home/airflow/.local/lib/python3.9/site-packages/selenium/webdriver/remote/remote_connection.py", line 428, in _request
    response = self._conn.request(method, url, body=body, headers=headers, timeout=self._client_config.timeout)
  File "/home/airflow/.local/lib/python3.9/site-packages/urllib3/request.py", line 81, in request
    return self.request_encode_body(
  File "/home/airflow/.local/lib/python3.9/site-packages/urllib3/request.py", line 173, in request_encode_body
    return self.urlopen(method, url, **extra_kw)
  File "/home/airflow/.local/lib/python3.9/site-packages/urllib3/poolmanager.py", line 376, in urlopen
    response = conn.urlopen(method, u.request_uri, **kw)
  File "/home/airflow/.local/lib/python3.9/site-packages/urllib3/connectionpool.py", line 716, in urlopen
    httplib_response = self._make_request(
  File "/home/airflow/.local/lib/python3.9/site-packages/urllib3/connectionpool.py", line 468, in _make_request
    six.raise_from(e, None)
  File "<string>", line 3, in raise_from
  File "/home/airflow/.local/lib/python3.9/site-packages/urllib3/connectionpool.py", line 463, in _make_request
    httplib_response = conn.getresponse()
  File "/usr/local/lib/python3.9/http/client.py", line 1377, in getresponse
    response.begin()
  File "/usr/local/lib/python3.9/http/client.py", line 320, in begin
    version, status, reason = self._read_status()
  File "/usr/local/lib/python3.9/http/client.py", line 281, in _read_status
    line = str(self.fp.readline(_MAXLINE + 1), "iso-8859-1")
  File "/usr/local/lib/python3.9/socket.py", line 716, in readinto
    return self._sock.recv_into(b)
  File "/home/airflow/.local/lib/python3.9/site-packages/airflow/models/taskinstance.py", line 3095, in signal_handler
    raise AirflowTaskTerminated("Task received SIGTERM signal")
airflow.exceptions.AirflowTaskTerminated: Task received SIGTERM signal

During handling of the above exception, another exception occurred:

Traceback (most recent call last):
  File "/home/airflow/.local/lib/python3.9/site-packages/urllib3/connection.py", line 174, in _new_conn
    conn = connection.create_connection(
  File "/home/airflow/.local/lib/python3.9/site-packages/urllib3/util/connection.py", line 95, in create_connection
    raise err
  File "/home/airflow/.local/lib/python3.9/site-packages/urllib3/util/connection.py", line 85, in create_connection
    sock.connect(sa)
ConnectionRefusedError: [Errno 111] Connection refused

During handling of the above exception, another exception occurred:

Traceback (most recent call last):
  File "/home/airflow/.local/lib/python3.9/site-packages/urllib3/connectionpool.py", line 716, in urlopen
    httplib_response = self._make_request(
  File "/home/airflow/.local/lib/python3.9/site-packages/urllib3/connectionpool.py", line 416, in _make_request
    conn.request(method, url, **httplib_request_kw)
  File "/home/airflow/.local/lib/python3.9/site-packages/urllib3/connection.py", line 244, in request
    super(HTTPConnection, self).request(method, url, body=body, headers=headers)
  File "/usr/local/lib/python3.9/http/client.py", line 1285, in request
    self._send_request(method, url, body, headers, encode_chunked)
  File "/usr/local/lib/python3.9/http/client.py", line 1331, in _send_request
    self.endheaders(body, encode_chunked=encode_chunked)
  File "/usr/local/lib/python3.9/http/client.py", line 1280, in endheaders
    self._send_output(message_body, encode_chunked=encode_chunked)
  File "/usr/local/lib/python3.9/http/client.py", line 1040, in _send_output
    self.send(msg)
  File "/usr/local/lib/python3.9/http/client.py", line 980, in send
    self.connect()
  File "/home/airflow/.local/lib/python3.9/site-packages/urllib3/connection.py", line 205, in connect
    conn = self._new_conn()
  File "/home/airflow/.local/lib/python3.9/site-packages/urllib3/connection.py", line 186, in _new_conn
    raise NewConnectionError(
urllib3.exceptions.NewConnectionError: <urllib3.connection.HTTPConnection object at 0x7f3a0da24a00>: Failed to establish a new connection: [Errno 111] Connection refused

During handling of the above exception, another exception occurred:

Traceback (most recent call last):
  File "/home/airflow/.local/lib/python3.9/site-packages/airflow/models/taskinstance.py", line 767, in _execute_task
    result = _execute_callable(context=context, **execute_callable_kwargs)
  File "/home/airflow/.local/lib/python3.9/site-packages/airflow/models/taskinstance.py", line 733, in _execute_callable
    return ExecutionCallableRunner(
  File "/home/airflow/.local/lib/python3.9/site-packages/airflow/utils/operator_helpers.py", line 252, in run
    return self.func(*args, **kwargs)
  File "/home/airflow/.local/lib/python3.9/site-packages/airflow/models/baseoperator.py", line 422, in wrapper
    return func(self, *args, **kwargs)
  File "/home/airflow/.local/lib/python3.9/site-packages/airflow/operators/python.py", line 238, in execute
    return_value = self.execute_callable()
  File "/home/airflow/.local/lib/python3.9/site-packages/airflow/operators/python.py", line 256, in execute_callable
    return runner.run(*self.op_args, **self.op_kwargs)
  File "/home/airflow/.local/lib/python3.9/site-packages/airflow/utils/operator_helpers.py", line 252, in run
    return self.func(*args, **kwargs)
  File "/opt/src/extract_scripts/extract.py", line 265, in genre_scraper
    driver.close()
  File "/home/airflow/.local/lib/python3.9/site-packages/selenium/webdriver/remote/webdriver.py", line 495, in close
    self.execute(Command.CLOSE)
  File "/home/airflow/.local/lib/python3.9/site-packages/selenium/webdriver/remote/webdriver.py", line 382, in execute
    response = self.command_executor.execute(driver_command, params)
  File "/home/airflow/.local/lib/python3.9/site-packages/selenium/webdriver/remote/remote_connection.py", line 404, in execute
    return self._request(command_info[0], url, body=data)
  File "/home/airflow/.local/lib/python3.9/site-packages/selenium/webdriver/remote/remote_connection.py", line 428, in _request
    response = self._conn.request(method, url, body=body, headers=headers, timeout=self._client_config.timeout)
  File "/home/airflow/.local/lib/python3.9/site-packages/urllib3/request.py", line 77, in request
    return self.request_encode_url(
  File "/home/airflow/.local/lib/python3.9/site-packages/urllib3/request.py", line 99, in request_encode_url
    return self.urlopen(method, url, **extra_kw)
  File "/home/airflow/.local/lib/python3.9/site-packages/urllib3/poolmanager.py", line 376, in urlopen
    response = conn.urlopen(method, u.request_uri, **kw)
  File "/home/airflow/.local/lib/python3.9/site-packages/urllib3/connectionpool.py", line 830, in urlopen
    return self.urlopen(
  File "/home/airflow/.local/lib/python3.9/site-packages/urllib3/connectionpool.py", line 830, in urlopen
    return self.urlopen(
  File "/home/airflow/.local/lib/python3.9/site-packages/urllib3/connectionpool.py", line 830, in urlopen
    return self.urlopen(
  File "/home/airflow/.local/lib/python3.9/site-packages/urllib3/connectionpool.py", line 802, in urlopen
    retries = retries.increment(
  File "/home/airflow/.local/lib/python3.9/site-packages/urllib3/util/retry.py", line 594, in increment
    raise MaxRetryError(_pool, url, error or ResponseError(cause))
urllib3.exceptions.MaxRetryError: HTTPConnectionPool(host='localhost', port=56799): Max retries exceeded with url: /session/0965b632ea0d8fcd9aaffcaf37565c9a/window (Caused by NewConnectionError('<urllib3.connection.HTTPConnection object at 0x7f3a0da24a00>: Failed to establish a new connection: [Errno 111] Connection refused'))
[2025-01-16T15:33:32.987+0000] {taskinstance.py:1225} INFO - Marking task as FAILED. dag_id=movie_pipeline, task_id=scrape_genre, run_id=manual__2025-01-16T04:38:13.822674+00:00, execution_date=20250116T043813, start_date=20250116T153008, end_date=20250116T153332
[2025-01-16T15:33:33.109+0000] {taskinstance.py:340} INFO - ::group::Post task execution logs
[2025-01-16T15:33:33.112+0000] {standard_task_runner.py:124} ERROR - Failed to execute job 40 for task scrape_genre (HTTPConnectionPool(host='localhost', port=56799): Max retries exceeded with url: /session/0965b632ea0d8fcd9aaffcaf37565c9a/window (Caused by NewConnectionError('<urllib3.connection.HTTPConnection object at 0x7f3a0da24a00>: Failed to establish a new connection: [Errno 111] Connection refused')); 1776)
Traceback (most recent call last):
  File "/opt/src/extract_scripts/extract.py", line 244, in genre_scraper
    driver.get(genre_link_us_box_office_collection_sorted)
  File "/home/airflow/.local/lib/python3.9/site-packages/selenium/webdriver/remote/webdriver.py", line 393, in get
    self.execute(Command.GET, {"url": url})
  File "/home/airflow/.local/lib/python3.9/site-packages/selenium/webdriver/remote/webdriver.py", line 382, in execute
    response = self.command_executor.execute(driver_command, params)
  File "/home/airflow/.local/lib/python3.9/site-packages/selenium/webdriver/remote/remote_connection.py", line 404, in execute
    return self._request(command_info[0], url, body=data)
  File "/home/airflow/.local/lib/python3.9/site-packages/selenium/webdriver/remote/remote_connection.py", line 428, in _request
    response = self._conn.request(method, url, body=body, headers=headers, timeout=self._client_config.timeout)
  File "/home/airflow/.local/lib/python3.9/site-packages/urllib3/request.py", line 81, in request
    return self.request_encode_body(
  File "/home/airflow/.local/lib/python3.9/site-packages/urllib3/request.py", line 173, in request_encode_body
    return self.urlopen(method, url, **extra_kw)
  File "/home/airflow/.local/lib/python3.9/site-packages/urllib3/poolmanager.py", line 376, in urlopen
    response = conn.urlopen(method, u.request_uri, **kw)
  File "/home/airflow/.local/lib/python3.9/site-packages/urllib3/connectionpool.py", line 716, in urlopen
    httplib_response = self._make_request(
  File "/home/airflow/.local/lib/python3.9/site-packages/urllib3/connectionpool.py", line 468, in _make_request
    six.raise_from(e, None)
  File "<string>", line 3, in raise_from
  File "/home/airflow/.local/lib/python3.9/site-packages/urllib3/connectionpool.py", line 463, in _make_request
    httplib_response = conn.getresponse()
  File "/usr/local/lib/python3.9/http/client.py", line 1377, in getresponse
    response.begin()
  File "/usr/local/lib/python3.9/http/client.py", line 320, in begin
    version, status, reason = self._read_status()
  File "/usr/local/lib/python3.9/http/client.py", line 281, in _read_status
    line = str(self.fp.readline(_MAXLINE + 1), "iso-8859-1")
  File "/usr/local/lib/python3.9/socket.py", line 716, in readinto
    return self._sock.recv_into(b)
  File "/home/airflow/.local/lib/python3.9/site-packages/airflow/models/taskinstance.py", line 3095, in signal_handler
    raise AirflowTaskTerminated("Task received SIGTERM signal")
airflow.exceptions.AirflowTaskTerminated: Task received SIGTERM signal

During handling of the above exception, another exception occurred:

Traceback (most recent call last):
  File "/home/airflow/.local/lib/python3.9/site-packages/urllib3/connection.py", line 174, in _new_conn
    conn = connection.create_connection(
  File "/home/airflow/.local/lib/python3.9/site-packages/urllib3/util/connection.py", line 95, in create_connection
    raise err
  File "/home/airflow/.local/lib/python3.9/site-packages/urllib3/util/connection.py", line 85, in create_connection
    sock.connect(sa)
ConnectionRefusedError: [Errno 111] Connection refused

During handling of the above exception, another exception occurred:

Traceback (most recent call last):
  File "/home/airflow/.local/lib/python3.9/site-packages/urllib3/connectionpool.py", line 716, in urlopen
    httplib_response = self._make_request(
  File "/home/airflow/.local/lib/python3.9/site-packages/urllib3/connectionpool.py", line 416, in _make_request
    conn.request(method, url, **httplib_request_kw)
  File "/home/airflow/.local/lib/python3.9/site-packages/urllib3/connection.py", line 244, in request
    super(HTTPConnection, self).request(method, url, body=body, headers=headers)
  File "/usr/local/lib/python3.9/http/client.py", line 1285, in request
    self._send_request(method, url, body, headers, encode_chunked)
  File "/usr/local/lib/python3.9/http/client.py", line 1331, in _send_request
    self.endheaders(body, encode_chunked=encode_chunked)
  File "/usr/local/lib/python3.9/http/client.py", line 1280, in endheaders
    self._send_output(message_body, encode_chunked=encode_chunked)
  File "/usr/local/lib/python3.9/http/client.py", line 1040, in _send_output
    self.send(msg)
  File "/usr/local/lib/python3.9/http/client.py", line 980, in send
    self.connect()
  File "/home/airflow/.local/lib/python3.9/site-packages/urllib3/connection.py", line 205, in connect
    conn = self._new_conn()
  File "/home/airflow/.local/lib/python3.9/site-packages/urllib3/connection.py", line 186, in _new_conn
    raise NewConnectionError(
urllib3.exceptions.NewConnectionError: <urllib3.connection.HTTPConnection object at 0x7f3a0da24a00>: Failed to establish a new connection: [Errno 111] Connection refused

During handling of the above exception, another exception occurred:

Traceback (most recent call last):
  File "/home/airflow/.local/lib/python3.9/site-packages/airflow/task/task_runner/standard_task_runner.py", line 117, in _start_by_fork
    ret = args.func(args, dag=self.dag)
  File "/home/airflow/.local/lib/python3.9/site-packages/airflow/cli/cli_config.py", line 49, in command
    return func(*args, **kwargs)
  File "/home/airflow/.local/lib/python3.9/site-packages/airflow/utils/cli.py", line 116, in wrapper
    return f(*args, **kwargs)
  File "/home/airflow/.local/lib/python3.9/site-packages/airflow/cli/commands/task_command.py", line 483, in task_run
    task_return_code = _run_task_by_selected_method(args, _dag, ti)
  File "/home/airflow/.local/lib/python3.9/site-packages/airflow/cli/commands/task_command.py", line 256, in _run_task_by_selected_method
    return _run_raw_task(args, ti)
  File "/home/airflow/.local/lib/python3.9/site-packages/airflow/cli/commands/task_command.py", line 341, in _run_raw_task
    return ti._run_raw_task(
  File "/home/airflow/.local/lib/python3.9/site-packages/airflow/utils/session.py", line 97, in wrapper
    return func(*args, session=session, **kwargs)
  File "/home/airflow/.local/lib/python3.9/site-packages/airflow/models/taskinstance.py", line 3005, in _run_raw_task
    return _run_raw_task(
  File "/home/airflow/.local/lib/python3.9/site-packages/airflow/models/taskinstance.py", line 273, in _run_raw_task
    TaskInstance._execute_task_with_callbacks(
  File "/home/airflow/.local/lib/python3.9/site-packages/airflow/models/taskinstance.py", line 3159, in _execute_task_with_callbacks
    result = self._execute_task(context, task_orig)
  File "/home/airflow/.local/lib/python3.9/site-packages/airflow/models/taskinstance.py", line 3183, in _execute_task
    return _execute_task(self, context, task_orig)
  File "/home/airflow/.local/lib/python3.9/site-packages/airflow/models/taskinstance.py", line 767, in _execute_task
    result = _execute_callable(context=context, **execute_callable_kwargs)
  File "/home/airflow/.local/lib/python3.9/site-packages/airflow/models/taskinstance.py", line 733, in _execute_callable
    return ExecutionCallableRunner(
  File "/home/airflow/.local/lib/python3.9/site-packages/airflow/utils/operator_helpers.py", line 252, in run
    return self.func(*args, **kwargs)
  File "/home/airflow/.local/lib/python3.9/site-packages/airflow/models/baseoperator.py", line 422, in wrapper
    return func(self, *args, **kwargs)
  File "/home/airflow/.local/lib/python3.9/site-packages/airflow/operators/python.py", line 238, in execute
    return_value = self.execute_callable()
  File "/home/airflow/.local/lib/python3.9/site-packages/airflow/operators/python.py", line 256, in execute_callable
    return runner.run(*self.op_args, **self.op_kwargs)
  File "/home/airflow/.local/lib/python3.9/site-packages/airflow/utils/operator_helpers.py", line 252, in run
    return self.func(*args, **kwargs)
  File "/opt/src/extract_scripts/extract.py", line 265, in genre_scraper
    driver.close()
  File "/home/airflow/.local/lib/python3.9/site-packages/selenium/webdriver/remote/webdriver.py", line 495, in close
    self.execute(Command.CLOSE)
  File "/home/airflow/.local/lib/python3.9/site-packages/selenium/webdriver/remote/webdriver.py", line 382, in execute
    response = self.command_executor.execute(driver_command, params)
  File "/home/airflow/.local/lib/python3.9/site-packages/selenium/webdriver/remote/remote_connection.py", line 404, in execute
    return self._request(command_info[0], url, body=data)
  File "/home/airflow/.local/lib/python3.9/site-packages/selenium/webdriver/remote/remote_connection.py", line 428, in _request
    response = self._conn.request(method, url, body=body, headers=headers, timeout=self._client_config.timeout)
  File "/home/airflow/.local/lib/python3.9/site-packages/urllib3/request.py", line 77, in request
    return self.request_encode_url(
  File "/home/airflow/.local/lib/python3.9/site-packages/urllib3/request.py", line 99, in request_encode_url
    return self.urlopen(method, url, **extra_kw)
  File "/home/airflow/.local/lib/python3.9/site-packages/urllib3/poolmanager.py", line 376, in urlopen
    response = conn.urlopen(method, u.request_uri, **kw)
  File "/home/airflow/.local/lib/python3.9/site-packages/urllib3/connectionpool.py", line 830, in urlopen
    return self.urlopen(
  File "/home/airflow/.local/lib/python3.9/site-packages/urllib3/connectionpool.py", line 830, in urlopen
    return self.urlopen(
  File "/home/airflow/.local/lib/python3.9/site-packages/urllib3/connectionpool.py", line 830, in urlopen
    return self.urlopen(
  File "/home/airflow/.local/lib/python3.9/site-packages/urllib3/connectionpool.py", line 802, in urlopen
    retries = retries.increment(
  File "/home/airflow/.local/lib/python3.9/site-packages/urllib3/util/retry.py", line 594, in increment
    raise MaxRetryError(_pool, url, error or ResponseError(cause))
urllib3.exceptions.MaxRetryError: HTTPConnectionPool(host='localhost', port=56799): Max retries exceeded with url: /session/0965b632ea0d8fcd9aaffcaf37565c9a/window (Caused by NewConnectionError('<urllib3.connection.HTTPConnection object at 0x7f3a0da24a00>: Failed to establish a new connection: [Errno 111] Connection refused'))
[2025-01-16T15:33:33.156+0000] {process_utils.py:80} INFO - Process psutil.Process(pid=1776, status='terminated', exitcode=1, started='15:30:08') (1776) terminated with exit code 1
[2025-01-16T15:33:33.158+0000] {process_utils.py:80} INFO - Process psutil.Process(pid=1822, status='terminated', started='15:30:09') (1822) terminated with exit code None
